2019-04-27 20:22:00,887 ERROR: Exception on /user/Ahmed/sendEmail [POST] [in /home/ahmnouira/Desktop/blog_flask/Ahmed_blog/ahmed-nouira-blog4-V0.1.0/venv/lib/python3.5/site-packages/flask/app.py:1761]
Traceback (most recent call last):
  File "/home/ahmnouira/Desktop/blog_flask/Ahmed_blog/ahmed-nouira-blog4-V0.1.0/venv/lib/python3.5/site-packages/flask/app.py", line 2292, in wsgi_app
    response = self.full_dispatch_request()
  File "/home/ahmnouira/Desktop/blog_flask/Ahmed_blog/ahmed-nouira-blog4-V0.1.0/venv/lib/python3.5/site-packages/flask/app.py", line 1815, in full_dispatch_request
    rv = self.handle_user_exception(e)
  File "/home/ahmnouira/Desktop/blog_flask/Ahmed_blog/ahmed-nouira-blog4-V0.1.0/venv/lib/python3.5/site-packages/flask/app.py", line 1718, in handle_user_exception
    reraise(exc_type, exc_value, tb)
  File "/home/ahmnouira/Desktop/blog_flask/Ahmed_blog/ahmed-nouira-blog4-V0.1.0/venv/lib/python3.5/site-packages/flask/_compat.py", line 35, in reraise
    raise value
  File "/home/ahmnouira/Desktop/blog_flask/Ahmed_blog/ahmed-nouira-blog4-V0.1.0/venv/lib/python3.5/site-packages/flask/app.py", line 1813, in full_dispatch_request
    rv = self.dispatch_request()
  File "/home/ahmnouira/Desktop/blog_flask/Ahmed_blog/ahmed-nouira-blog4-V0.1.0/venv/lib/python3.5/site-packages/flask/app.py", line 1799, in dispatch_request
    return self.view_functions[rule.endpoint](**req.view_args)
  File "/home/ahmnouira/Desktop/blog_flask/Ahmed_blog/ahmed-nouira-blog4-V0.1.0/venv/lib/python3.5/site-packages/flask_login/utils.py", line 261, in decorated_view
    return func(*args, **kwargs)
  File "/home/ahmnouira/Desktop/blog_flask/Ahmed_blog/ahmed-nouira-blog4-V0.1.0/app/routes.py", line 191, in send_Email
    return redirect(url_for('send_Email'))
  File "/home/ahmnouira/Desktop/blog_flask/Ahmed_blog/ahmed-nouira-blog4-V0.1.0/venv/lib/python3.5/site-packages/flask/helpers.py", line 356, in url_for
    return appctx.app.handle_url_build_error(error, endpoint, values)
  File "/home/ahmnouira/Desktop/blog_flask/Ahmed_blog/ahmed-nouira-blog4-V0.1.0/venv/lib/python3.5/site-packages/flask/app.py", line 2061, in handle_url_build_error
    reraise(exc_type, exc_value, tb)
  File "/home/ahmnouira/Desktop/blog_flask/Ahmed_blog/ahmed-nouira-blog4-V0.1.0/venv/lib/python3.5/site-packages/flask/_compat.py", line 35, in reraise
    raise value
  File "/home/ahmnouira/Desktop/blog_flask/Ahmed_blog/ahmed-nouira-blog4-V0.1.0/venv/lib/python3.5/site-packages/flask/helpers.py", line 345, in url_for
    force_external=external)
  File "/home/ahmnouira/Desktop/blog_flask/Ahmed_blog/ahmed-nouira-blog4-V0.1.0/venv/lib/python3.5/site-packages/werkzeug/routing.py", line 1776, in build
    raise BuildError(endpoint, values, method, self)
werkzeug.routing.BuildError: Could not build url for endpoint 'send_Email'. Did you forget to specify values ['username']?
